2022-12-02 03:26:55,132 ERROR: Exception on /reset_password_request [POST] [in /usr/local/lib/python3.10/dist-packages/flask/app.py:1741]
Traceback (most recent call last):
  File "/usr/local/lib/python3.10/dist-packages/flask/app.py", line 2525, in wsgi_app
    response = self.full_dispatch_request()
  File "/usr/local/lib/python3.10/dist-packages/flask/app.py", line 1822, in full_dispatch_request
    rv = self.handle_user_exception(e)
  File "/usr/local/lib/python3.10/dist-packages/flask/app.py", line 1820, in full_dispatch_request
    rv = self.dispatch_request()
  File "/usr/local/lib/python3.10/dist-packages/flask/app.py", line 1796, in dispatch_request
    return self.ensure_sync(self.view_functions[rule.endpoint])(**view_args)
  File "/media/hossam/C858381B58380B28/microblog/app/routes.py", line 70, in reset_password_request
    send_password_reset_email(user)
  File "/media/hossam/C858381B58380B28/microblog/app/email.py", line 14, in send_password_reset_email
    token = user.get_reset_password_token()
  File "/media/hossam/C858381B58380B28/microblog/app/models.py", line 72, in get_reset_password_token
    {'reset_password': self.id, "exp": datetime.datetime.now(tz=timezone.utc) + datetime.timedelta(seconds=expires_in)}, app.Config['SECRET_KEY'],algorithm='HS256')
AttributeError: type object 'datetime.datetime' has no attribute 'datetime'
2022-12-02 03:27:39,260 INFO: Microblog startup [in /media/hossam/C858381B58380B28/microblog/app/__init__.py:46]
2022-12-02 03:27:42,764 ERROR: Exception on /reset_password_request [POST] [in /usr/local/lib/python3.10/dist-packages/flask/app.py:1741]
Traceback (most recent call last):
  File "/usr/local/lib/python3.10/dist-packages/flask/app.py", line 2525, in wsgi_app
    response = self.full_dispatch_request()
  File "/usr/local/lib/python3.10/dist-packages/flask/app.py", line 1822, in full_dispatch_request
    rv = self.handle_user_exception(e)
  File "/usr/local/lib/python3.10/dist-packages/flask/app.py", line 1820, in full_dispatch_request
    rv = self.dispatch_request()
  File "/usr/local/lib/python3.10/dist-packages/flask/app.py", line 1796, in dispatch_request
    return self.ensure_sync(self.view_functions[rule.endpoint])(**view_args)
  File "/media/hossam/C858381B58380B28/microblog/app/routes.py", line 70, in reset_password_request
    send_password_reset_email(user)
  File "/media/hossam/C858381B58380B28/microblog/app/email.py", line 14, in send_password_reset_email
    token = user.get_reset_password_token()
  File "/media/hossam/C858381B58380B28/microblog/app/models.py", line 72, in get_reset_password_token
    {'reset_password': self.id, "exp": datetime.now(tz=timezone.utc) + timedelta(seconds=expires_in)}, app.Config['SECRET_KEY'],algorithm='HS256')
TypeError: 'type' object is not subscriptable
2022-12-02 03:29:29,296 INFO: Microblog startup [in /media/hossam/C858381B58380B28/microblog/app/__init__.py:46]
2022-12-02 03:29:34,527 ERROR: Exception on /reset_password_request [POST] [in /usr/local/lib/python3.10/dist-packages/flask/app.py:1741]
Traceback (most recent call last):
  File "/usr/local/lib/python3.10/dist-packages/flask/app.py", line 2525, in wsgi_app
    response = self.full_dispatch_request()
  File "/usr/local/lib/python3.10/dist-packages/flask/app.py", line 1822, in full_dispatch_request
    rv = self.handle_user_exception(e)
  File "/usr/local/lib/python3.10/dist-packages/flask/app.py", line 1820, in full_dispatch_request
    rv = self.dispatch_request()
  File "/usr/local/lib/python3.10/dist-packages/flask/app.py", line 1796, in dispatch_request
    return self.ensure_sync(self.view_functions[rule.endpoint])(**view_args)
  File "/media/hossam/C858381B58380B28/microblog/app/routes.py", line 70, in reset_password_request
    send_password_reset_email(user)
  File "/media/hossam/C858381B58380B28/microblog/app/email.py", line 14, in send_password_reset_email
    token = user.get_reset_password_token()
  File "/media/hossam/C858381B58380B28/microblog/app/models.py", line 72, in get_reset_password_token
    {'reset_password': self.id, "exp": datetime.now() + timedelta(seconds=expires_in)}, app.Config['SECRET_KEY'],algorithm='HS256')
TypeError: 'type' object is not subscriptable
2022-12-02 03:31:34,756 INFO: Microblog startup [in /media/hossam/C858381B58380B28/microblog/app/__init__.py:46]
2022-12-02 03:31:39,104 ERROR: Exception on /reset_password_request [POST] [in /usr/local/lib/python3.10/dist-packages/flask/app.py:1741]
Traceback (most recent call last):
  File "/usr/local/lib/python3.10/dist-packages/flask/app.py", line 2525, in wsgi_app
    response = self.full_dispatch_request()
  File "/usr/local/lib/python3.10/dist-packages/flask/app.py", line 1822, in full_dispatch_request
    rv = self.handle_user_exception(e)
  File "/usr/local/lib/python3.10/dist-packages/flask/app.py", line 1820, in full_dispatch_request
    rv = self.dispatch_request()
  File "/usr/local/lib/python3.10/dist-packages/flask/app.py", line 1796, in dispatch_request
    return self.ensure_sync(self.view_functions[rule.endpoint])(**view_args)
  File "/media/hossam/C858381B58380B28/microblog/app/routes.py", line 70, in reset_password_request
    send_password_reset_email(user)
  File "/media/hossam/C858381B58380B28/microblog/app/email.py", line 14, in send_password_reset_email
    token = user.get_reset_password_token()
  File "/media/hossam/C858381B58380B28/microblog/app/models.py", line 72, in get_reset_password_token
    {'reset_password': self.id, "exp": datetime.datetime.now(tz=timezone.utc) + datetime.timedelta(seconds=30)}, app.Config['SECRET_KEY'],algorithm='HS256')
AttributeError: type object 'datetime.datetime' has no attribute 'datetime'
2022-12-02 03:32:17,499 INFO: Microblog startup [in /media/hossam/C858381B58380B28/microblog/app/__init__.py:46]
2022-12-02 03:32:22,748 ERROR: Exception on /reset_password_request [POST] [in /usr/local/lib/python3.10/dist-packages/flask/app.py:1741]
Traceback (most recent call last):
  File "/usr/local/lib/python3.10/dist-packages/flask/app.py", line 2525, in wsgi_app
    response = self.full_dispatch_request()
  File "/usr/local/lib/python3.10/dist-packages/flask/app.py", line 1822, in full_dispatch_request
    rv = self.handle_user_exception(e)
  File "/usr/local/lib/python3.10/dist-packages/flask/app.py", line 1820, in full_dispatch_request
    rv = self.dispatch_request()
  File "/usr/local/lib/python3.10/dist-packages/flask/app.py", line 1796, in dispatch_request
    return self.ensure_sync(self.view_functions[rule.endpoint])(**view_args)
  File "/media/hossam/C858381B58380B28/microblog/app/routes.py", line 70, in reset_password_request
    send_password_reset_email(user)
  File "/media/hossam/C858381B58380B28/microblog/app/email.py", line 14, in send_password_reset_email
    token = user.get_reset_password_token()
  File "/media/hossam/C858381B58380B28/microblog/app/models.py", line 72, in get_reset_password_token
    {'reset_password': self.id, "exp": datetime.now(tz=timezone.utc) + timedelta(seconds=30)}, app.Config['SECRET_KEY'],algorithm='HS256')
TypeError: 'type' object is not subscriptable
2022-12-02 03:32:58,403 INFO: Microblog startup [in /media/hossam/C858381B58380B28/microblog/app/__init__.py:46]
2022-12-02 03:33:02,541 ERROR: Exception on /reset_password_request [POST] [in /usr/local/lib/python3.10/dist-packages/flask/app.py:1741]
Traceback (most recent call last):
  File "/usr/local/lib/python3.10/dist-packages/flask/app.py", line 2525, in wsgi_app
    response = self.full_dispatch_request()
  File "/usr/local/lib/python3.10/dist-packages/flask/app.py", line 1822, in full_dispatch_request
    rv = self.handle_user_exception(e)
  File "/usr/local/lib/python3.10/dist-packages/flask/app.py", line 1820, in full_dispatch_request
    rv = self.dispatch_request()
  File "/usr/local/lib/python3.10/dist-packages/flask/app.py", line 1796, in dispatch_request
    return self.ensure_sync(self.view_functions[rule.endpoint])(**view_args)
  File "/media/hossam/C858381B58380B28/microblog/app/routes.py", line 70, in reset_password_request
    send_password_reset_email(user)
  File "/media/hossam/C858381B58380B28/microblog/app/email.py", line 14, in send_password_reset_email
    token = user.get_reset_password_token()
  File "/media/hossam/C858381B58380B28/microblog/app/models.py", line 74, in get_reset_password_token
    {'reset_password': self.id, "exp": datetime.now(tz=timezone.utc) + timedelta(seconds=30)}, app.Config['SECRET_KEY'],algorithm='HS256')
TypeError: 'type' object is not subscriptable
2022-12-02 03:33:05,570 ERROR: Exception on /reset_password_request [POST] [in /usr/local/lib/python3.10/dist-packages/flask/app.py:1741]
Traceback (most recent call last):
  File "/usr/local/lib/python3.10/dist-packages/flask/app.py", line 2525, in wsgi_app
    response = self.full_dispatch_request()
  File "/usr/local/lib/python3.10/dist-packages/flask/app.py", line 1822, in full_dispatch_request
    rv = self.handle_user_exception(e)
  File "/usr/local/lib/python3.10/dist-packages/flask/app.py", line 1820, in full_dispatch_request
    rv = self.dispatch_request()
  File "/usr/local/lib/python3.10/dist-packages/flask/app.py", line 1796, in dispatch_request
    return self.ensure_sync(self.view_functions[rule.endpoint])(**view_args)
  File "/media/hossam/C858381B58380B28/microblog/app/routes.py", line 70, in reset_password_request
    send_password_reset_email(user)
  File "/media/hossam/C858381B58380B28/microblog/app/email.py", line 14, in send_password_reset_email
    token = user.get_reset_password_token()
  File "/media/hossam/C858381B58380B28/microblog/app/models.py", line 74, in get_reset_password_token
    {'reset_password': self.id, "exp": datetime.now(tz=timezone.utc) + timedelta(seconds=30)}, app.Config['SECRET_KEY'],algorithm='HS256')
TypeError: 'type' object is not subscriptable
2022-12-02 03:33:38,326 INFO: Microblog startup [in /media/hossam/C858381B58380B28/microblog/app/__init__.py:46]
